Workbook

Sheet ECUs_DDets_Region
A1: Region | B1: Sector | C1: Subsector | D1: Variable | E1: Technology | F1: UE_Type | G1: FE_Type | H1: Temp_level | I1: Subtech | J1: Drive | K1: Forecast data | L1: Function | M1: Equation | N1: DDr1 | O1: DDr2 | P1: DDr3 | Q1: Unit | R1: Factor | S1: k0 | T1: k1 | U1: k2 | V1: k3 | W1: k4 | X1: Source/Assumption | Y1: 2015 | Z1: 2016 | AA1: 2017 | AB1: 2018 | AC1: 2019 | AD1: 2020 | AE1: 2021 | AF1: 2022 | AG1: 2023 | AH1: 2024 | AI1: 2025 | AJ1: 2030 | AK1: 2040 | AL1: 2050 | AM1: 2100 | AN1: Source / Assumption | AO1: Lower limit | AP1: Upper limit
A2: default | B2: default | C2: default | D2: EFFICIENCY | E2: default | F2: ELEC | G2: ELEC | H2: TOTAL | I2: default | J2: default | K2: User | L2: const | M2: {=_xlfn.XLOOKUP(L2, 'Function options'!$A$2:$A$22, 'Function options'!$B$2:B$22, "Not found")} -> y = const = k0 | Q2: % | R2: 0.01 | S2: 100 | AO2: 0
A3: default | B3: default | C3: default | D3: EFFICIENCY | E3: default | F3: HEAT | G3: GAS | H3: default | I3: default | J3: default | K3: User | L3: const | M3: {=_xlfn.XLOOKUP(L3, 'Function options'!$A$2:$A$22, 'Function options'!$B$2:B$22, "Not found")} -> y = const = k0 | Q3: % | R3: 0.01 | S3: 93 | AO3: 0
A4: default | B4: default | C4: default | D4: EFFICIENCY | E4: default | F4: HEAT | G4: H2 | H4: default | I4: default | J4: default | K4: User | L4: const | M4: {=_xlfn.XLOOKUP(L4, 'Function options'!$A$2:$A$22, 'Function options'!$B$2:B$22, "Not found")} -> y = const = k0 | Q4: % | R4: 0.01 | S4: 100 | AO4: 0
A5: default | B5: default | C5: default | D5: EFFICIENCY | E5: default | F5: HEAT | G5: ELEC | H5: TOTAL | I5: default | J5: default | K5: User | L5: const | M5: {=_xlfn.XLOOKUP(L5, 'Function options'!$A$2:$A$22, 'Function options'!$B$2:B$22, "Not found")} -> y = const = k0 | Q5: % | R5: 0.01 | S5: 100 | AO5: 0
A6: default | B6: IND | C6: default | D6: EFFICIENCY | E6: default | F6: HEAT | G6: ELEC | H6: Q1 | I6: default | J6: default | K6: User | L6: const | M6: {=_xlfn.XLOOKUP(L6, 'Function options'!$A$2:$A$22, 'Function options'!$B$2:B$22, "Not found")} -> y = const = k0 | Q6: % | R6: 0.01 | S6: 100 | AO6: 0
A7: default | B7: default | C7: default | D7: EFFICIENCY | E7: default | F7: HEAT | G7: ELEC | H7: Q2 | I7: default | J7: default | K7: User | L7: const | M7: {=_xlfn.XLOOKUP(L7, 'Function options'!$A$2:$A$22, 'Function options'!$B$2:B$22, "Not found")} -> y = const = k0 | Q7: % | R7: 0.01 | S7: 100 | AO7: 0
A8: default | B8: default | C8: default | D8: EFFICIENCY | E8: default | F8: HEAT | G8: ELEC | H8: Q3 | I8: default | J8: default | K8: User | L8: const | M8: {=_xlfn.XLOOKUP(L8, 'Function options'!$A$2:$A$22, 'Function options'!$B$2:B$22, "Not found")} -> y = const = k0 | Q8: % | R8: 0.01 | S8: 100 | AO8: 0
A9: default | B9: default | C9: default | D9: EFFICIENCY | E9: default | F9: HEAT | G9: ELEC | H9: Q4 | I9: default | J9: default | K9: User | L9: const | M9: {=_xlfn.XLOOKUP(L9, 'Function options'!$A$2:$A$22, 'Function options'!$B$2:B$22, "Not found")} -> y = const = k0 | Q9: % | R9: 0.01 | S9: 100 | AO9: 0
A10: default | B10: default | C10: default | D10: EFFICIENCY | E10: default | F10: H2 | G10: H2 | H10: TOTAL | I10: default | J10: default | K10: User | L10: const | M10: {=_xlfn.XLOOKUP(L10, 'Function options'!$A$2:$A$22, 'Function options'!$B$2:B$22, "Not found")} -> y = const = k0 | Q10: % | R10: 0.01 | S10: 100 | AO10: 0
A11: default | B11: default | C11: default | D11: FE_SHARE_FOR_UE | E11: default | F11: ELEC | G11: ELEC | H11: TOTAL | I11: default | J11: default | K11: User | L11: const | M11: {=_xlfn.XLOOKUP(L11, 'Function options'!$A$2:$A$22, 'Function options'!$B$2:B$22, "Not found")} -> y = const = k0 | N11: TIME | Q11: % | R11: 0.01 | S11: 100 | AO11: 0
A12: default | B12: default | C12: default | D12: FE_SHARE_FOR_UE | E12: default | F12: H2 | G12: H2 | H12: TOTAL | I12: default | J12: default | K12: User | L12: const | M12: {=_xlfn.XLOOKUP(L12, 'Function options'!$A$2:$A$22, 'Function options'!$B$2:B$22, "Not found")} -> y = const = k0 | N12: TIME | Q12: % | R12: 0.01 | S12: 100 | AO12: 0
A13: default | B13: IND | C13: default | D13: FE_SHARE_FOR_UE | E13: default | F13: HEAT | G13: ELEC | H13: Q1 | I13: default | J13: default | K13: User | L13: interp_lin | M13: {=_xlfn.XLOOKUP(L13, 'Function options'!$A$2:$A$22, 'Function options'!$B$2:B$22, "Not found")} -> lin interpolation between given points - based on driver as x-aches | N13: TIME | Q13: % | R13: 0.01 | Y13: =AB13 -> 0 | AB13: =AD13 -> 0 | AI13: 0 | AL13: 0 | AO13: 0
A14: default | B14: IND | C14: default | D14: FE_SHARE_FOR_UE | E14: default | F14: HEAT | G14: ELEC | H14: Q2 | I14: default | J14: default | K14: User | L14: interp_lin | M14: {=_xlfn.XLOOKUP(L14, 'Function options'!$A$2:$A$22, 'Function options'!$B$2:B$22, "Not found")} -> lin interpolation between given points - based on driver as x-aches | N14: TIME | Q14: % | R14: 0.01 | Y14: =AB14 -> 0 | AB14: =AD14 -> 0 | AI14: 0 | AL14: 100 | AO14: 0
A15: default | B15: IND | C15: default | D15: FE_SHARE_FOR_UE | E15: default | F15: HEAT | G15: ELEC | H15: Q3 | I15: default | J15: default | K15: User | L15: interp_lin | M15: {=_xlfn.XLOOKUP(L15, 'Function options'!$A$2:$A$22, 'Function options'!$B$2:B$22, "Not found")} -> lin interpolation between given points - based on driver as x-aches | N15: TIME | Q15: % | R15: 0.01 | Y15: =AB15 -> 0 | AB15: =AD15 -> 0 | AI15: 0 | AL15: 100 | AO15: 0
A16: default | B16: IND | C16: default | D16: FE_SHARE_FOR_UE | E16: default | F16: HEAT | G16: ELEC | H16: Q4 | I16: default | J16: default | K16: User | L16: interp_lin | M16: {=_xlfn.XLOOKUP(L16, 'Function options'!$A$2:$A$22, 'Function options'!$B$2:B$22, "Not found")} -> lin interpolation between given points - based on driver as x-aches | N16: TIME | Q16: % | R16: 0.01 | Y16: =AB16 -> 0 | AB16: =AD16 -> 0 | AI16: 0 | AL16: 100 | AO16: 0
A17: default | B17: IND | C17: default | D17: FE_SHARE_FOR_UE | E17: default | F17: HEAT | G17: ELEC | H17: Q5 | I17: default | J17: default | K17: User | L17: interp_lin | M17: {=_xlfn.XLOOKUP(L17, 'Function options'!$A$2:$A$22, 'Function options'!$B$2:B$22, "Not found")} -> lin interpolation between given points - based on driver as x-aches | N17: TIME | Q17: % | R17: 0.01 | Y17: =AB17 -> 0 | AB17: =AD17 -> 0 | AL17: 0 | AO17: 0
A18: default | B18: IND | C18: default | D18: FE_SHARE_FOR_UE | E18: default | F18: HEAT | G18: GAS | H18: TOTAL | I18: default | J18: default | K18: User | L18: interp_lin | M18: {=_xlfn.XLOOKUP(L18, 'Function options'!$A$2:$A$22, 'Function options'!$B$2:B$22, "Not found")} -> lin interpolation between given points - based on driver as x-aches | N18: TIME | Q18: % | R18: 0.01 | Y18: =AB18 -> 0 | AB18: 0 | AL18: 0 | AO18: 0
A19: default | B19: IND | C19: default | D19: FE_SHARE_FOR_UE | E19: default | F19: HEAT | G19: GAS | H19: Q1 | I19: default | J19: default | K19: User | L19: interp_lin | M19: {=_xlfn.XLOOKUP(L19, 'Function options'!$A$2:$A$22, 'Function options'!$B$2:B$22, "Not found")} -> lin interpolation between given points - based on driver as x-aches | N19: TIME | Q19: % | R19: 0.01 | Y19: 100 | AB19: 100 | AI19: 100 | AL19: 50 | AO19: 0
A20: default | B20: IND | C20: default | D20: FE_SHARE_FOR_UE | E20: default | F20: HEAT | G20: GAS | H20: Q2 | I20: default | J20: default | K20: User | L20: interp_lin | M20: {=_xlfn.XLOOKUP(L20, 'Function options'!$A$2:$A$22, 'Function options'!$B$2:B$22, "Not found")} -> lin interpolation between given points - based on driver as x-aches | N20: TIME | Q20: % | R20: 0.01 | Y20: =AB20 -> 100 | AB20: 100 | AI20: 100 | AL20: 0 | AO20: 0
A21: default | B21: IND | C21: default | D21: FE_SHARE_FOR_UE | E21: default | F21: HEAT | G21: GAS | H21: Q3 | I21: default | J21: default | K21: User | L21: interp_lin | M21: {=_xlfn.XLOOKUP(L21, 'Function options'!$A$2:$A$22, 'Function options'!$B$2:B$22, "Not found")} -> lin interpolation between given points - based on driver as x-aches | N21: TIME | Q21: % | R21: 0.01 | Y21: =AB21 -> 100 | AB21: 100 | AI21: 100 | AL21: 0 | AO21: 0
A22: default | B22: IND | C22: default | D22: FE_SHARE_FOR_UE | E22: default | F22: HEAT | G22: GAS | H22: Q4 | I22: default | J22: default | K22: User | L22: interp_lin | M22: {=_xlfn.XLOOKUP(L22, 'Function options'!$A$2:$A$22, 'Function options'!$B$2:B$22, "Not found")} -> lin interpolation between given points - based on driver as x-aches | N22: TIME | Q22: % | R22: 0.01 | Y22: =AB22 -> 100 | AB22: 100 | AI22: 100 | AL22: 0 | AO22: 0
A23: default | B23: IND | C23: default | D23: FE_SHARE_FOR_UE | E23: default | F23: HEAT | G23: GAS | H23: Q5 | I23: default | J23: default | K23: User | L23: interp_lin | M23: {=_xlfn.XLOOKUP(L23, 'Function options'!$A$2:$A$22, 'Function options'!$B$2:B$22, "Not found")} -> lin interpolation between given points - based on driver as x-aches | N23: TIME | Q23: % | R23: 0.01 | Y23: =AB23 -> 0 | AB23: =AD23 -> 0 | AL23: 0 | AO23: 0
A24: default | B24: IND | C24: default | D24: FE_SHARE_FOR_UE | E24: default | F24: HEAT | G24: H2 | H24: TOTAL | I24: default | J24: default | K24: User | L24: interp_lin | M24: {=_xlfn.XLOOKUP(L24, 'Function options'!$A$2:$A$22, 'Function options'!$B$2:B$22, "Not found")} -> lin interpolation between given points - based on driver as x-aches | N24: TIME | Q24: % | R24: 0.01 | Y24: =AB24 -> 0 | AB24: 0 | AL24: 0 | AO24: 0
A25: default | B25: IND | C25: default | D25: FE_SHARE_FOR_UE | E25: default | F25: HEAT | G25: H2 | H25: Q1 | I25: default | J25: default | K25: User | L25: interp_lin | M25: {=_xlfn.XLOOKUP(L25, 'Function options'!$A$2:$A$22, 'Function options'!$B$2:B$22, "Not found")} -> lin interpolation between given points - based on driver as x-aches | N25: TIME | Q25: % | R25: 0.01 | Y25: =AB25 -> 0 | AB25: =AD25 -> 0 | AI25: =AJ25 -> 0 | AL25: 0 | AO25: 0
A26: default | B26: IND | C26: default | D26: FE_SHARE_FOR_UE | E26: default | F26: HEAT | G26: H2 | H26: Q2 | I26: default | J26: default | K26: User | L26: interp_lin | M26: {=_xlfn.XLOOKUP(L26, 'Function options'!$A$2:$A$22, 'Function options'!$B$2:B$22, "Not found")} -> lin interpolation between given points - based on driver as x-aches | N26: TIME | Q26: % | R26: 0.01 | Y26: =AB26 -> 0 | AB26: =AD26 -> 0 | AI26: =AJ26 -> 0 | AL26: 0 | AO26: 0
A27: default | B27: IND | C27: default | D27: FE_SHARE_FOR_UE | E27: default | F27: HEAT | G27: H2 | H27: Q3 | I27: default | J27: default | K27: User | L27: interp_lin | M27: {=_xlfn.XLOOKUP(L27, 'Function options'!$A$2:$A$22, 'Function options'!$B$2:B$22, "Not found")} -> lin interpolation between given points - based on driver as x-aches | N27: TIME | Q27: % | R27: 0.01 | Y27: =AB27 -> 0 | AB27: =AD27 -> 0 | AI27: =AJ27 -> 0 | AL27: 0 | AO27: 0
A28: default | B28: IND | C28: default | D28: FE_SHARE_FOR_UE | E28: default | F28: HEAT | G28: H2 | H28: Q4 | I28: default | J28: default | K28: User | L28: interp_lin | M28: {=_xlfn.XLOOKUP(L28, 'Function options'!$A$2:$A$22, 'Function options'!$B$2:B$22, "Not found")} -> lin interpolation between given points - based on driver as x-aches | N28: TIME | Q28: % | R28: 0.01 | Y28: =AB28 -> 0 | AB28: =AD28 -> 0 | AI28: =AJ28 -> 0 | AL28: 0 | AO28: 0
A29: default | B29: IND | C29: default | D29: FE_SHARE_FOR_UE | E29: default | F29: HEAT | G29: H2 | H29: Q5 | I29: default | J29: default | K29: User | L29: interp_lin | M29: {=_xlfn.XLOOKUP(L29, 'Function options'!$A$2:$A$22, 'Function options'!$B$2:B$22, "Not found")} -> lin interpolation between given points - based on driver as x-aches | N29: TIME | Q29: % | R29: 0.01 | Y29: =AB29 -> 0 | AB29: =AD29 -> 0 | AL29: 0 | AO29: 0
A30: default | B30: IND | C30: default | D30: PROD_QUANT | K30: Historical | L30: lin_share | M30: {=_xlfn.XLOOKUP(L30, 'Function options'!$A$2:$A$22, 'Function options'!$B$2:B$22, "Not found")} -> y = k0 + (k1 + k2*DDr1)*DDr2 | N30: TIME | O30: POP | Q30: Tausend ton | R30: 1000 | AO30: 0
A31: default | B31: IND | C31: default | D31: SPEC_EN_QUANT | E31: default | F31: HEAT | H31: Q1 | K31: Historical | L31: const_last | M31: {=_xlfn.XLOOKUP(L31, 'Function options'!$A$2:$A$22, 'Function options'!$B$2:B$22, "Not found")} -> y = const = y(t_hist) | Q31: % | R31: 0.01 | AO31: 0
A32: default | B32: IND | C32: default | D32: SPEC_EN_QUANT | E32: default | F32: HEAT | H32: Q2 | K32: Historical | L32: const_last | M32: {=_xlfn.XLOOKUP(L32, 'Function options'!$A$2:$A$22, 'Function options'!$B$2:B$22, "Not found")} -> y = const = y(t_hist) | Q32: % | R32: 0.01 | AO32: 0
A33: default | B33: IND | C33: default | D33: SPEC_EN_QUANT | E33: default | F33: HEAT | H33: Q3 | K33: Historical | L33: const_last | M33: {=_xlfn.XLOOKUP(L33, 'Function options'!$A$2:$A$22, 'Function options'!$B$2:B$22, "Not found")} -> y = const = y(t_hist) | Q33: % | R33: 0.01 | AO33: 0
A34: default | B34: IND | C34: default | D34: SPEC_EN_QUANT | E34: default | F34: HEAT | H34: Q4 | K34: Historical | L34: const_last | M34: {=_xlfn.XLOOKUP(L34, 'Function options'!$A$2:$A$22, 'Function options'!$B$2:B$22, "Not found")} -> y = const = y(t_hist) | Q34: % | R34: 0.01 | AO34: 0
A35: default | B35: IND | C35: default | D35: SPEC_EN_QUANT | E35: default | F35: HEAT | H35: Q5 | K35: Historical | L35: const_last | M35: {=_xlfn.XLOOKUP(L35, 'Function options'!$A$2:$A$22, 'Function options'!$B$2:B$22, "Not found")} -> y = const = y(t_hist) | Q35: % | R35: 0.01 | AO35: 0
A36: default | B36: IND | C36: STEEL_PRIM | D36: SPEC_EN_QUANT | E36: BOF | F36: ELEC | K36: Historical | L36: const_last | M36: y = const = y(t_hist) | N36: TIME | Q36: GJ/t | R36: 2.7777778e-07 | S36: 0 | T36: 1.82 | U36: -1 | V36: 2020 | AO36: 1.269967
A37: default | B37: IND | C37: STEEL_PRIM | D37: SPEC_EN_QUANT | E37: BOF | F37: H2 | K37: Historical | L37: const_last | M37: y = const = y(t_hist) | N37: TIME | Q37: GJ/t | R37: 2.7777778e-07 | S37: 0 | T37: 0 | U37: -1 | V37: 2020 | AO37: 0
A38: default | B38: IND | C38: STEEL_PRIM | D38: SPEC_EN_QUANT | E38: BOF | F38: HEAT | K38: Historical | L38: const_last | M38: y = const = y(t_hist) | N38: TIME | Q38: GJ/t | R38: 2.7777778e-07 | S38: 0 | T38: 19.39 | U38: -1 | V38: 2020 | AO38: 12.17703
A39: default | B39: IND | C39: STEEL_PRIM | D39: SPEC_EN_QUANT | E39: DRI | F39: ELEC | K39: Historical | L39: const_last | M39: y = const = y(t_hist) | N39: TIME | Q39: GJ/t | R39: 2.7777778e-07 | S39: 0 | T39: 1.116 | U39: -1 | V39: 2020 | AO39: 1.116
A40: default | B40: IND | C40: STEEL_PRIM | D40: SPEC_EN_QUANT | E40: DRI | F40: H2 | K40: Historical | L40: const_last | M40: y = const = y(t_hist) | N40: TIME | Q40: GJ/t | R40: 2.7777778e-07 | S40: 0 | T40: 6.4073592 | U40: -1 | V40: 2020 | AO40: 6.4073592
...

Sheet Demand_Drivers
A1: Top-Region | B1: Region | C1: Sector | D1: Subsector | E1: Variable | F1: Technology | G1: UE_Type | H1: FE_Type | I1: Temp_level | J1: Subtech | K1: Drive | L1: Forecast data | M1: Function | N1: Equation | O1: DDr1 | P1: DDr2 | Q1: DDr3 | R1: DDr4 | S1: DDr5 | T1: Unit | U1: Factor | V1: k0 | W1: k1 | X1: k2 | Y1: k3 | Z1: k4 | AA1: Source/Assumption | AB1: Source / Assumption | AC1: Lower limit | AD1: 2010 | AE1: 2011 | AF1: 2012 | AG1: 2013 | AH1: 2014 | AI1: 2015 | AJ1: 2016 | AK1: 2017 | AL1: 2018 | AM1: 2019 | AN1: 2020 | AO1: 2021 | AP1: 2022 | AQ1: 2023 | AR1: 2024 | AS1: 2025 | AT1: 2026 | AU1: 2027 | AV1: 2028 | AW1: 2029 | AX1: 2030 | AY1: 2031 | AZ1: 2032 | BA1: 2033 | BB1: 2034 | BC1: 2035 | BD1: 2036 | BE1: 2037 | BF1: 2038 | BG1: 2039 | BH1: 2040 | BI1: 2041 | BJ1: 2042 | BK1: 2043 | BL1: 2044 | BM1: 2045 | BN1: 2046 | BO1: 2047 | BP1: 2048 | BQ1: 2049 | BR1: 2050 | BS1: 2051 | BT1: 2052 | BU1: 2053 | BV1: 2054 | BW1: 2055 | BX1: 2056 | BY1: 2057 | BZ1: 2058 | CA1: 2059 | CB1: 2060 | CC1: 2061 | CD1: 2062 | CE1: 2063 | CF1: 2064 | CG1: 2065 | CH1: 2066 | CI1: 2067 | CJ1: 2068 | CK1: 2069 | CL1: 2070 | CM1: 2071 | CN1: 2072 | CO1: 2073 | CP1: 2074 | CQ1: 2075 | CR1: 2076 | CS1: 2077 | CT1: 2078 | CU1: 2079 | CV1: 2080 | CW1: 2081 | CX1: 2082 | CY1: 2083 | CZ1: 2084 | DA1: 2085 | DB1: 2086 | DC1: 2087 | DD1: 2088 | DE1: 2089 | DF1: 2090 | DG1: 2091 | DH1: 2092 | DI1: 2093 | DJ1: 2094 | DK1: 2095 | DL1: 2096 | DM1: 2097 | DN1: 2098 | DO1: 2099 | DP1: 2100
A2: Europe | B2: Germany | C2: default | D2: default | E2: POP | F2: default | L2: User | M2: interp_lin | N2: {=_xlfn.XLOOKUP(M2,'Function options'!$A$2:$A$17, 'Function options'!$B$2:B$17, "Not found")} -> lin interpolation between given points - based on driver as x-aches | O2: TIME | U2: 1 | AS2: 83199070 | AT2: 83134877 | AU2: 83058838 | AV2: 82971794 | AW2: 82873294 | AX2: 82762676 | AY2: 82643647 | AZ2: 82515756 | BA2: 82377569 | BB2: 82230377 | BC2: 82073885 | BD2: 81910193 | BE2: 81742143 | BF2: 81569127 | BG2: 81389362 | BH2: 81201104 | BI2: 81006025 | BJ2: 80804806 | BK2: 80596076 | BL2: 80379919 | BM2: 80157776 | BN2: 79928543 | BO2: 79691578 | BP2: 79446826 | BQ2: 79193152 | BR2: 78932228 | BS2: 78665188 | BT2: 78391674 | BU2: 78112717 | BV2: 77830769 | BW2: 77545526 | BX2: 77257540 | BY2: 76969951 | BZ2: 76685629 | CA2: 76405360 | CB2: 76130209 | CC2: 75862236 | CD2: 75602683 | CE2: 75353041 | CF2: 75113485 | CG2: 74884119 | CH2: 74663932 | CI2: 74450625 | CJ2: 74243912 | CK2: 74043688 | CL2: 73848370 | CM2: 73655672 | CN2: 73463457 | CO2: 73270699 | CP2: 73077408 | CQ2: 72883376 | CR2: 72689184 | CS2: 72495166 | CT2: 72299996 | CU2: 72104751 | CV2: 71910856 | CW2: 71717186 | CX2: 71523820 | CY2: 71332955 | CZ2: 71145752 | DA2: 70963141 | DB2: 70784979 | DC2: 70611359 | DD2: 70444086 | DE2: 70284069 | DF2: 70130955 | DG2: 69983583 | DH2: 69842458 | DI2: 69709011 | DJ2: 69582707 | DK2: 69462191 | DL2: 69347300 | DM2: 69237823 | DN2: 69133244 | DO2: 69033371 | DP2: 68936103

Sheet Subregional_division
A1: Region | B1: Subregion | C1: Sector | D1: Subsector | E1: Variable | F1: Technology | G1: UE_Type | H1: FE_Type | I1: Temp_level | J1: Subtech | K1: Drive | L1: Forecast data | M1: Function | N1: Equation | O1: DDr1 | P1: DDr2 | Q1: DDr3 | R1: DDr4 | S1: DDr5 | T1: Unit | U1: Factor | V1: k0 | W1: k1 | X1: k2 | Y1: k3 | Z1: k4 | AA1: Source / Assumption | AB1: Lower limit | AC1: 2010 | AD1: 2011 | AE1: 2012 | AF1: 2013 | AG1: 2014 | AH1: 2015 | AI1: 2016 | AJ1: 2017 | AK1: 2018 | AL1: 2019 | AM1: 2020 | AN1: 2021 | AO1: 2022 | AP1: 2023 | AQ1: 2024 | AR1: 2025 | AS1: 2026 | AT1: 2027 | AU1: 2028 | AV1: 2029 | AW1: 2030 | AX1: 2031 | AY1: 2032 | AZ1: 2033 | BA1: 2034 | BB1: 2035 | BC1: 2036 | BD1: 2037 | BE1: 2038 | BF1: 2039 | BG1: 2040 | BH1: 2041 | BI1: 2042 | BJ1: 2043 | BK1: 2044 | BL1: 2045 | BM1: 2046 | BN1: 2047 | BO1: 2048 | BP1: 2049 | BQ1: 2050 | BR1: 2051 | BS1: 2052 | BT1: 2053 | BU1: 2054 | BV1: 2055 | BW1: 2056 | BX1: 2057 | BY1: 2058 | BZ1: 2059 | CA1: 2060 | CB1: 2061 | CC1: 2062 | CD1: 2063 | CE1: 2064 | CF1: 2065 | CG1: 2066 | CH1: 2067 | CI1: 2068 | CJ1: 2069 | CK1: 2070 | CL1: 2071 | CM1: 2072 | CN1: 2073 | CO1: 2074 | CP1: 2075 | CQ1: 2076 | CR1: 2077 | CS1: 2078 | CT1: 2079 | CU1: 2080 | CV1: 2081 | CW1: 2082 | CX1: 2083 | CY1: 2084 | CZ1: 2085 | DA1: 2086 | DB1: 2087 | DC1: 2088 | DD1: 2089 | DE1: 2090 | DF1: 2091 | DG1: 2092 | DH1: 2093 | DI1: 2094 | DJ1: 2095 | DK1: 2096 | DL1: 2097 | DM1: 2098 | DN1: 2099 | DO1: 2100
A2: default | B2: default | C2: default | D2: default | E2: DIST_PROD | L2: Historical | M2: const_last | N2: {=_xlfn.XLOOKUP(M2,'Function options'!$A$2:$A$17, 'Function options'!$B$2:B$17, "Not found")} -> y = const = y(t_hist)

Sheet Function options
A1: Function | B1: Equation | C1: Applicable for Forecast data
A2: lin | B2: y = k0 + k1*DDr1 + k2*DDr2 + … | C2: Historical and User
A3: exp | B3: y = k0 + k1 * ((1 + k2 / 100) ^ (DDr1 - k3)) | C3: User
A4: interp_lin | B4: lin interpolation between given points - based on driver as x-aches | C4: User | D4: Just enter the two Pionts in the year-colum, th code compiles automaticlly the two entered points
A5: const | B5: y = const = k0 | C5: User
A6: const_last | B6: y = const = y(t_hist) | C6: Historical
A7: const_mean | B7: y = const = avg of all y(t_hist)) | C7: Historical
A8: const_mult_div | B8: y = k0 * (DDr1 / DDr2) | C8: User
A9: lin_mult_div | B9: y = k0 + (k1 + k2*DDr1)*DDr2/DDr3 | C9: User
A10: lin_share | B10: y = k0 + (k1 + k2*DDr1)*DDr2 | C10: Historical
A11: exp_mult_div | B11: y = k0 + k1 * ((1 + k2 / 100) ^ (DDr1 - k3)) * DDr2/DDr3 | C11: User
A12: mult | B12: y = k0 + k1 *DDr1*DDr2*DDr3… | C12: User
A13: mult_k0_zero | B13: y = k1 *DDr1*DDr2*DDr3… | C13: Historical and User
A14: exp_sum | B14: y = k0 + k1*e^(k2*x1) + k3*e^(k4*x2) + … | C14: Historical and User
A15: log_sum | B15: y = k0 + k1*log(x1) + k2*log(x2) + ... | C15: Historical and User
A16: power_sum | B16: y= k0 + (k1*x1)^k2 +( k3*x2)^k4 +.. | C16: Historical and User
... A19: user_mult | B19: y = k0*k1*DDr1 + k2*DDr2 | C19: User
A20: user_function | C20: User
A21: user_function | C21: User
A22: user_function | C22: User
A32: Importand! | B32: Type as function name: "user_...", otherwise it will not recognize it as user function
A39: User Funktion | B39: Syntax
A40: coefficians | B40: k0, k1,…
A41: Demand Drivers | B41: DDr1, DDr2, …
A42: Power | B42: x**a or x^a or pow(x, a)
A43: Minimum | B43: min(a, b)
A44: Maximum | B44: max(a, b)
A45: Absolute Value | B45: abs(x)
A46: Square root | B46: sqrt(x)
A47: Nat. log | B47: log(x)
A48: Base 10 log | B48: log10(x)
A49: Exponential | B49: exp(x)
... A51: Round up | B51: ceil(x)

Sheet info
A2: Description: | B2: The variables highlighted with "own assumption" are hypothetical. This is for demonstrative purposes only to illustrate the model's input-output mechanics and predictive capabilities.
C4: Description
A5: Source: | B5: [1] | C5: based on Database from the tool | D5: A. Kerekeš and L. Breuning, endemo, 2024. Accessed: Aug. 28 2025. [Online]. Available: https://​github.com​/​tum-​ens/​endemo
