Workbook

Sheet steel
A1: Country | B1: Spec energy consumption [GJ/t] | C1: Spec electricity consumption [GJ/t] | D1: Spec heat consumption [GJ/t] | E1: max. subst. of heat with H2 [%] | F1: Spec hydrogen consumption [GJ/t]
A2: all | B2: =C2+D2+F2 -> 19.53 | C2: 1.4 | D2: 18.13 | E2: 0 | F2: 0

Sheet steel_prim
A1: Country | B1: Spec energy consumption [GJ/t] | C1: Spec electricity consumption [GJ/t] | D1: Spec heat consumption [GJ/t] | E1: max. subst. of heat with H2 [%] | F1: Spec hydrogen consumption [GJ/t]
A2: all | B2: =C2+D2+F2 -> 21.21 | C2: =1.4+0.42 -> 1.82 | D2: =18.13+1.26 -> 19.39 | E2: 0 | F2: 0

Sheet steel_sec
A1: Country | B1: Spec energy consumption [GJ/t] | C1: Spec electricity consumption [GJ/t] | D1: Spec heat consumption [GJ/t] | E1: max. subst. of heat with H2 [%] | F1: Spec hydrogen consumption [GJ/t]
A2: all | B2: =C2+D2+F2 -> 4.45 | C2: =1.91+0.42 -> 2.33 | D2: =0.86+1.26 -> 2.12 | E2: 0 | F2: 0

Sheet steel_direct
A1: Country | B1: Spec energy consumption [GJ/t] | C1: Spec electricity consumption [GJ/t] | D1: Spec heat consumption [GJ/t] | E1: max. subst. of heat with H2 [%] | F1: Spec hydrogen consumption [GJ/t]
A2: all | B2: =C2+F2 -> 7.5233592 | C2: =0.828+0.288 -> 1.116 | D2: 0 | E2: 0 | F2: =53.4*33.33*3.6/1000 -> 6.4073592

Sheet alu_prim
A1: Country | B1: Spec energy consumption [GJ/t] | C1: Spec electricity consumption [GJ/t] | D1: Spec heat consumption [GJ/t] | E1: max. subst. of heat with H2 [%] | F1: Spec hydrogen consumption [GJ/t] | H1: Comment for max. subst.
A2: all | B2: =C2+D2 -> 68.43 | C2: =52.2+5.76 -> 57.96 | D2: =3.27+7.2 -> 10.47 | E2: 20 | F2: 0 | H2: Assumption

Sheet alu_sec
A1: Country | B1: Spec energy consumption [GJ/t] | C1: Spec electricity consumption [GJ/t] | D1: Spec heat consumption [GJ/t] | E1: max. subst. of heat with H2 [%] | F1: Spec hydrogen consumption [GJ/t] | H1: Comment for max. subst.
A2: all | B2: =C2+D2 -> 23.76 | C2: =1.8+5.76 -> 7.56 | D2: =9+7.2 -> 16.2 | E2: 20 | F2: 0 | H2: Assumption

Sheet copper_prim
A1: Country | B1: Spec energy consumption [GJ/t] | C1: Spec electricity consumption [GJ/t] | D1: Spec heat consumption [GJ/t] | E1: max. subst. of heat with H2 [%] | F1: Spec hydrogen consumption [GJ/t] | H1: Comment for max. subst.
A2: all | B2: =C2+D2 -> 23.65 | C2: =2.77+5.4 -> 8.17 | D2: =7.92+7.56 -> 15.48 | E2: 20 | F2: 0 | H2: Assumption

Sheet glass
A1: Country | B1: Spec energy consumption [GJ/t] | C1: Spec electricity consumption [GJ/t] | D1: Spec heat consumption [GJ/t] | E1: max. subst. of heat with H2 [%] | F1: Spec hydrogen consumption [GJ/t] | G1: Comment for max. subst.
A2: Belgium | B2: 9.066086 | C2: 1.5833107 | D2: 7.4827753 | E2: 20 | F2: 0 | G2: Assumption
A3: Bulgaria | B3: 9.7237368 | C3: 1.3806853 | D3: 8.3430515 | E3: 20 | F3: 0
A4: Denmark | B4: 7.0720666 | C4: 2.4479405 | D4: 4.624126 | E4: 20 | F4: 0
A5: Germany | B5: 7.5230587 | C5: 1.3898961 | D5: 6.1331626 | E5: 20 | F5: 0
A6: Ireland | B6: 11.901192 | C6: 2.9658267 | D6: 8.9353654 | E6: 20 | F6: 0
A7: Greece | B7: 7.0439687 | C7: 1.3377338 | D7: 5.7062349 | E7: 20 | F7: 0
A8: Spain | B8: 7.5701241 | C8: 1.2943897 | D8: 6.2757344 | E8: 20 | F8: 0
A9: France | B9: 8.1921938 | C9: 1.4449081 | D9: 6.7472857 | E9: 20 | F9: 0
A10: Croatia | B10: 9.974738 | C10: 2.1473226 | D10: 7.8274154 | E10: 20 | F10: 0
A11: Italy | B11: 7.1144663 | C11: 1.1266896 | D11: 5.9877767 | E11: 20 | F11: 0
A12: Latvia | B12: 13.7 | C12: 3.3839 | D12: 10.3161 | E12: 20 | F12: 0
A13: Lithuania | B13: 7.5 | C13: 3.375 | D13: 4.125 | E13: 20 | F13: 0
A14: Estonia | B14: 6.4 | C14: 0.992 | D14: 5.408 | E14: 20 | F14: 0
... A25: all | B25: 7.5230587 | C25: 1.3898961 | D25: 6.1331626 | E25: 20 | F25: 0

Sheet copper_sec
A1: Country | B1: Spec energy consumption [GJ/t] | C1: Spec electricity consumption [GJ/t] | D1: Spec heat consumption [GJ/t] | E1: max. subst. of heat with H2 [%] | F1: Spec hydrogen consumption [GJ/t] | H1: Comment for max. subst.
A2: all | B2: =C2+D2 -> 19.22 | C2: =2.3+5.4 -> 7.7 | D2: =3.96+7.56 -> 11.52 | E2: 20 | F2: 0 | H2: Assumption

Sheet cement
A1: Country | B1: Spec energy consumption [GJ/t] | C1: Spec electricity consumption [GJ/t] | D1: Spec heat consumption [GJ/t] | E1: max. subst. of heat with H2 [%] | F1: Spec hydrogen consumption [GJ/t] | G1: Comment for max. subst.
A2: Austria | B2: 3.05 | C2: =12.38/100*B2 -> 0.37759 | D2: =87.62/100*B2 -> 2.67241 | E2: 34 | F2: 0 | G2: Assumption
A3: Belgium | B3: 3.4 | C3: =12.38/100*B3 -> 0.42092 | D3: =87.62/100*B3 -> 2.97908 | E3: 34 | F3: 0
A4: Bulgaria | B4: 3.4 | C4: =12.38/100*B4 -> 0.42092 | D4: =87.62/100*B4 -> 2.97908 | E4: 34 | F4: 0
A5: Czechia | B5: 3.25 | C5: =12.38/100*B5 -> 0.40235 | D5: =87.62/100*B5 -> 2.84765 | E5: 34 | F5: 0
A6: Germany | B6: 3.3 | C6: =3.8*3600/34000 -> 0.40235294 | D6: =26.9*3600/34000 -> 2.8482353 | E6: 34 | F6: 0
A7: Spain | B7: 3.75 | C7: =12.38/100*B7 -> 0.46425 | D7: =87.62/100*B7 -> 3.28575 | E7: 34 | F7: 0
A8: Finland | B8: 3.4 | C8: =12.38/100*B8 -> 0.42092 | D8: =87.62/100*B8 -> 2.97908 | E8: 34 | F8: 0
A9: France | B9: 3.4 | C9: =12.38/100*B9 -> 0.42092 | D9: =87.62/100*B9 -> 2.97908 | E9: 34 | F9: 0
A10: Italy | B10: 3.25 | C10: =12.38/100*B10 -> 0.40235 | D10: =87.62/100*B10 -> 2.84765 | E10: 34 | F10: 0
A11: Poland | B11: 3.1 | C11: =12.38/100*B11 -> 0.38378 | D11: =87.62/100*B11 -> 2.71622 | E11: 34 | F11: 0
A12: Portugal | B12: 3.4 | C12: =12.38/100*B12 -> 0.42092 | D12: =87.62/100*B12 -> 2.97908 | E12: 34 | F12: 0
A13: Romania | B13: 3.4 | C13: =12.38/100*B13 -> 0.42092 | D13: =87.62/100*B13 -> 2.97908 | E13: 34 | F13: 0
A14: Slovenia | B14: 3.4 | C14: =12.38/100*B14 -> 0.42092 | D14: =87.62/100*B14 -> 2.97908 | E14: 34 | F14: 0
A15: Slovakia | B15: 3.4 | C15: =12.38/100*B15 -> 0.42092 | D15: =87.62/100*B15 -> 2.97908 | E15: 34 | F15: 0
A16: United Kingdom | B16: 3.2 | C16: =12.38/100*B16 -> 0.39616 | D16: =87.62/100*B16 -> 2.80384 | E16: 34 | F16: 0
A17: all | B17: 3.4 | C17: =12.38/100*B17 -> 0.42092 | D17: =87.62/100*B17 -> 2.97908 | E17: 34 | F17: 0

Sheet paper
A1: Country | B1: Spec energy consumption [GJ/t] | C1: Spec electricity consumption [GJ/t] | D1: Spec heat consumption [GJ/t] | E1: max. subst. of heat with H2 [%] | F1: Spec hydrogen consumption [GJ/t]
A2: all | B2: =C2+D2 -> 10.465487 | C2: =188*3600/226/1000 -> 2.9946903 | D2: =(65.7-18.8)*3600/22.6/1000 -> 7.4707965 | E2: 0 | F2: 0

Sheet chlorine
A1: Country | B1: Spec energy consumption [GJ/t] | C1: Spec electricity consumption [GJ/t] | D1: Spec heat consumption [GJ/t] | E1: max. subst. of heat with H2 [%] | F1: Spec hydrogen consumption [GJ/t]
A2: all | B2: =C2+D2 -> 9.5 | C2: 8.9 | D2: 0.6 | E2: 0 | F2: 0

Sheet ammonia
A1: Country | B1: Spec energy consumption [GJ/t] | C1: Spec electricity consumption [GJ/t] | D1: Spec heat consumption [GJ/t] | E1: max. subst. of heat with H2 [%] | F1: Spec hydrogen consumption [GJ/t]
A2: all | B2: =SUM(C2,D2,F2) -> 27.547864 | C2: =5+1.19 -> 6.19 | D2: 0 | E2: 0 | F2: =0.178*33.33*3.6 -> 21.357864

Sheet ammonia_classic
A1: Country | B1: Spec energy consumption [GJ/t] | C1: Spec electricity consumption [GJ/t] | D1: Spec heat consumption [GJ/t] | E1: max. subst. of heat with H2 [%] | F1: Spec hydrogen consumption [GJ/t]
A2: all | B2: =SUM(C2,D2,F2) -> 7.34 | C2: 0.74 | D2: =10.9-4.3 -> 6.6 | E2: 0 | F2: 0

Sheet methanol
A1: Country | B1: Spec energy consumption [GJ/t] | C1: Spec electricity consumption [GJ/t] | D1: Spec heat consumption [GJ/t] | E1: max. subst. of heat with H2 [%] | F1: Spec hydrogen consumption [GJ/t]
A2: all | B2: =C2+D2+F2 -> 28.077732 | C2: =5.4 -> 5.4 | D2: 0 | E2: 0 | F2: =0.189*1000*33.33*3600/1000000 -> 22.677732

Sheet methanol_classic
A1: Country | B1: Spec energy consumption [GJ/t] | C1: Spec electricity consumption [GJ/t] | D1: Spec heat consumption [GJ/t] | E1: max. subst. of heat with H2 [%] | F1: Spec hydrogen consumption [GJ/t]
A2: all | B2: =C2+D2+F2 -> 12.5 | C2: 0.6 | D2: =13.9-2 -> 11.9 | E2: 0 | F2: 0

Sheet ethylene
A1: Country | B1: Spec energy consumption [GJ/t] | C1: Spec electricity consumption [GJ/t] | D1: Spec heat consumption [GJ/t] | E1: max. subst. of heat with H2 [%] | F1: Spec hydrogen consumption [GJ/t]
A2: all | B2: =C2+D2+F2 -> 77.861544 | C2: =2.28*methanol!C2+5 -> 17.312 | D2: 0 | E2: 0 | F2: =2.67*methanol!F2 -> 60.549544

Sheet ethylene_classic
A1: Country | B1: Spec energy consumption [GJ/t] | C1: Spec electricity consumption [GJ/t] | D1: Spec heat consumption [GJ/t] | E1: max. subst. of heat with H2 [%] | F1: Spec hydrogen consumption [GJ/t]
A2: all | B2: =C2+D2+F2 -> 16.5 | C2: 0.8 | D2: =16.5-C2 -> 15.7 | E2: 0 | F2: 0

Sheet propylene
A1: Country | B1: Spec energy consumption [GJ/t] | C1: Spec electricity consumption [GJ/t] | D1: Spec heat consumption [GJ/t] | E1: max. subst. of heat with H2 [%] | F1: Spec hydrogen consumption [GJ/t]
A2: all | B2: =C2+D2+F2 -> 77.861544 | C2: =2.28*methanol!C2+5 -> 17.312 | D2: 0 | E2: 0 | F2: =2.67*methanol!F2 -> 60.549544

Sheet propylene_classic
A1: Country | B1: Spec energy consumption [GJ/t] | C1: Spec electricity consumption [GJ/t] | D1: Spec heat consumption [GJ/t] | E1: max. subst. of heat with H2 [%] | F1: Spec hydrogen consumption [GJ/t]
A2: all | B2: =C2+D2+F2 -> 16.5 | C2: 0.8 | D2: =16.5-C2 -> 15.7 | E2: 0 | F2: 0

Sheet olefins
A1: Country | B1: Spec energy consumption [GJ/t] | C1: Spec electricity consumption [GJ/t] | D1: Spec heat consumption [GJ/t] | E1: max. subst. of heat with H2 [%] | F1: Spec hydrogen consumption [GJ/t]
A2: all | B2: =C2+D2+F2 -> 77.861544 | C2: =2.28*methanol!C2+5 -> 17.312 | D2: 0 | E2: 0 | F2: =2.67*methanol!F2 -> 60.549544

Sheet olefins_classic
A1: Country | B1: Spec energy consumption [GJ/t] | C1: Spec electricity consumption [GJ/t] | D1: Spec heat consumption [GJ/t] | E1: max. subst. of heat with H2 [%] | F1: Spec hydrogen consumption [GJ/t]
A2: all | B2: =C2+D2+F2 -> 16.5 | C2: 0.8 | D2: =16.5-C2 -> 15.7 | E2: 0 | F2: 0

Sheet aromatics
A1: Country | B1: Spec energy consumption [GJ/t] | C1: Spec electricity consumption [GJ/t] | D1: Spec heat consumption [GJ/t] | E1: max. subst. of heat with H2 [%] | F1: Spec hydrogen consumption [GJ/t]
A2: all | B2: =C2+D2+F2 -> 125.73425 | C2: =4.3*methanol!C2 +5 -> 28.22 | D2: 0 | E2: 0 | F2: =4.3*methanol!F2 -> 97.514248

Sheet aromatics_classic
A1: Country | B1: Spec energy consumption [GJ/t] | C1: Spec electricity consumption [GJ/t] | D1: Spec heat consumption [GJ/t] | E1: max. subst. of heat with H2 [%] | F1: Spec hydrogen consumption [GJ/t]
A2: all | B2: =C2+D2+F2 -> 7 | C2: =7-D2 -> 0.34 | D2: =6.66 -> 6.66 | E2: 0 | F2: 0

Sheet Info
C1: Description | D1: Value | E1: Web | F1: Publisher | G1: Title | H1: Page | I1: Year | J1: Accessed | K1: Author
A2: steel
A3: Source: | B3: [1] | C3: oxygen steel "usully" in DE, spec fuel and electricity consumption | D3: fuel 18,13 GJ/t elec 0,39 MWh (=1,4 GJ/t) | E3: https://www.bmwi.de/Redaktion/DE/Downloads/E/energiewende-in-der-industrie-ap2a-branchensteckbrief-stahl.pdf?__blob=publicationFile&v=4 | F3: Navigant Energy Germany GmbH, Institut für Energiewirtschaft und Rationelle Energieanwendung, Forschungsgesellschaft für Energiewirtschaft, BBG und Partner | G3: Energiewende in der Industrie: Branchensteckbrief der Eisen- und Stahlindustrie | H3: p. 7 | I3: 2020 | J3: 02.11.2023
A5: Assumption: | B5: A1 | C5: Since primary and seconday steel are together observed, the specific consumption only of the primary steel (without additional consumption) is considered.
A7: Further Info: | B7: F1 | C7: Specific energy consumption in different European countries | E7: https://d-nb.info/1049260554/34 | H7: Fig. 3-17
A9: steel_prim
A10: Source: | B10: [1] | C10: oxygen steel "usully" in DE, spec fuel and electricity consumption | D10: fuel 18,13 + 1.26 GJ/t (0,35 MWh/t) Gas for warm rolling = 19.39 GJ/t elec 0,39 MWh (=1,4 GJ/t) + 0.42 GJ/t (0,117 MWh/t) for warm rolling = 1.82 GJ/t | E10: https://www.bmwi.de/Redaktion/DE/Downloads/E/energiewende-in-der-industrie-ap2a-branchensteckbrief-stahl.pdf?__blob=publicationFile&v=4 | F10: Navigant Energy Germany GmbH, Institut für Energiewirtschaft und Rationelle Energieanwendung, Forschungsgesellschaft für Energiewirtschaft, BBG und Partner | G10: Energiewende in der Industrie: Branchensteckbrief der Eisen- und Stahlindustrie | H10: p. 7,12 | I10: 2020 | J10: 02.11.2023
A12: Further Info: | B12: F1 | C12: Specific primary energy consumption | D12: 17.41 or 19.23 GJ/t (crude steel or steel products) | E12: https://issuu.com/stahlonline/docs/fakten_stahlindustrie_2014-04_6 | F12: https://www.stahl-online.de/wp-content/uploads/2013/12/Fakten_Stahlindustrie_2014-04_6.pdf
B13: F2 | C13: Generally - Facts regarding steel industry in Germany | E13: https://www.stahl-online.de/wp-content/uploads/WV-Stahl_Fakten-2020_rz_neu_Web1.pdf
B14: F3 | C14: Specific primary energy consumption | D14: Ca. 20GJ/t | E14: https://eneff-industrie.info/quickinfos/energieintensive-branchen/daten-zu-besonders-energiehungrigen-produktionsbereichen/
B15: F4 | C15: "Rohstoffeinsatz 2016" feedstock deployment 2016 | D15: Mainly coking coal | E15: https://issuu.com/stahlonline/docs/fakten_stahlindustrie_2017_rz_web_faa65d6cfd2e15 | F15: https://www.stahl-online.de/wp-content/uploads/2017/12/Fakten_Stahlindustrie_2017_rz_web.pdf
B16: F5 | C16: Energy flows | E16: https://www.bmu.de/fileadmin/Daten_BMU/Pools/Forschungsdatenbank/fkz_3712_12_102_energieeffizienzma%C3%9Fnahmen_bewertung_bf.pdf
B17: F6 | C17: Energy flows | E17: https://www.umweltbundesamt.de/sites/default/files/medien/367/dokumente/bvt-merkblatt_eisen-_und_stahlerzeugung_endfassung.pdf
A19: steel_sec
A20: Source: | B20: [1] | C20: oxygen steel "usully" in DE, spec fuel and electricity consumption | D20: fuel 191 (Kohlenstoffträger)+50 (Erdgas-Sauerstoffbrenner ) kWh / t = 0.86 GJ/t + 1.26 GJ/t (0,35 MWh/t) Gas for warm rolling = 2.12 GJ/t elec 0,530 MWh/t = 1.908 GJ/t + 0.42 GJ/t (0,117 MWh/t) for warm rolling = 2.33 GJ/t | E20: https://www.bmwi.de/Redaktion/DE/Downloads/E/energiewende-in-der-industrie-ap2a-branchensteckbrief-stahl.pdf?__blob=publicationFile&v=4 | F20: Navigant Energy Germany GmbH, Institut für Energiewirtschaft und Rationelle Energieanwendung, Forschungsgesellschaft für Energiewirtschaft, BBG und Partner | G20: Energiewende in der Industrie: Branchensteckbrief der Eisen- und Stahlindustrie | H20: p. 10,12 | I20: 2020 | J20: 02.11.2023
A22: steel_direct
A23: Source: | B23: [1] | C23: Direct reduction steel | D23: 635 m³ H2 (53,4kg) / t = 53.4kg*33.33kWh/kg = 6.4 GJ/t 0,23 MWh/t elec for preheating = 0.828 GJ/t 0,08 MWh/t elec for mechanical work = 0.288 GJ/t | E23: https://germany.arcelormittal.com/icc/arcelor/med/b8e/b8e0c15a-102c-d51d-b2a9-147d7b2f25d3,11111111-1111-1111-1111-111111111111.pdf | F23: Stahl und Eisen, Vol. 137, Nr. 6 | G23: Bewertung der Herstellung von Eisenschwamm unter Verwendung von Wasserstoff.pdf | I23: 2017 | J23: 02.11.2023 | K23: Hölling, Marc; Weng, Matthias; Gellert, Sebastian
A25: Further Info: | B25: F1 | C25: Process heat | E25: https://www.dena.de/fileadmin/dena/Publikationen/PDFs/2019/Factsheet_PowerFuels_Stahlproduktion_Industrielle_Prozesswaerme.pdf
B26: F2 | C26: US energy comparison | E26: https://www.hydrogen.energy.gov/pdfs/review19/sa172_elgowainy_2019_o.pdf | H26: p. 25
A28: alu_prim
A29: Source: | B29: [1] | C29: Electricity and fuel demand | D29: elec: 14,5 MWh/t = 52,2 GJ/t fuel: 4,78 MWh/t * 19% = 3.27 GJ/t (81% fuel demand for the anode) Casting (Gießen) elec: 1,6 MWh/t = 5,76 GJ/t fuel: 2,0 MWh/t = 7,2 GJ/t | E29: https://www.bmwk.de/Redaktion/DE/Downloads/E/energiewende-in-der-industrie-ap2a-branchensteckbrief-metall.pdf?__blob=publicationFile&v=4 | F29: Navigant Energy Germany GmbH, Institut für Energiewirtschaft und Rationelle Energieanwendung, Forschungsgesellschaft für Energiewirtschaft, BBG und Partner | G29: Energiewende in der Industrie: Branchensteckbrief der NE-Metallindustrie | I29: 2020 | J29: 02.11.2023
A31: Assumption: | B31: A1 | C31: Based on F2, fuel demand in [1] is considered as a process heat demand
A33: Further Info: | B33: F1 | C33: Fuel: Further processing and anode production Elec: electrolysis and further processing (alloying) | D33: fuel: 1.28+0.4 = 1.64 GJ/t elec: (13.9MWh/t = )50GJ/t + (126 kWh/t =)0.45 GJ/t + 2 GJ/t = 52.45 | E33: https://d-nb.info/1049260554/34
B34: F2 | C34: Electricity and process heat demand | D34: elec: 48.2 GJ/t process heat: 3.8 GJ/t | E34: https://www.umweltbundesamt.at/fileadmin/site/publikationen/REP0303.pdf | H34: p. 34 Table: "Input bei der Primäraluminium-Herstellung durch Schmelzflusselektrolyse pro Tonne Aluminium (GEMIS)"
A36: alu_sec
A37: Source: | B37: [1] | C37: Electricity and fuel demand | D37: elec: 0,5 MWh/t = 1.8 GJ/t fuel: 2,5 MWh/t = 9 GJ/t Casting (Gießen) elec: 1,6 MWh/t = 5,76 GJ/t fuel: 2,0 MWh/t = 7,2 GJ/t | E37: https://www.bmwk.de/Redaktion/DE/Downloads/E/energiewende-in-der-industrie-ap2a-branchensteckbrief-metall.pdf?__blob=publicationFile&v=4 | F37: Navigant Energy Germany GmbH, Institut für Energiewirtschaft und Rationelle Energieanwendung, Forschungsgesellschaft für Energiewirtschaft, BBG und Partner | G37: Energiewende in der Industrie: Branchensteckbrief der NE-Metallindustrie | I37: 2020 | J37: 02.11.2023
A39: Further Info: | B39: F1 | C39: Fuel for smelting and total energy demand | D39: fuel: 5,9 GJ/t for smelting total: 11.2 GJ/t | E39: https://d-nb.info/1049260554/34
B40: F2 | C40: Fuel and electricity demand | D40: fuel (4,4–4,7GJ/t) or (2,5–4,3GJ/t) Gas 3,53GJ/t or 3,81GJ/t elec: 0.4-0.9 GJ/t | E40: https://www.umweltbundesamt.at/fileadmin/site/publikationen/REP0303.pdf
A42: copper_prim
A43: Source: | B43: [1] | C43: Für die Primärkupferherstellung werden ab dem Kupferwerk etwa 0,77 MWh/t (Strom) verwendet. Herstellung von Primärkupfer fällt ab dem Kupferwerk bis zur Kathode | D43: elec: 0,77 MWh/t/1000*3600 = 2,77 GJ/t fuel: 2,2 MWh/t /1000*3600 = 7,92 GJ/t | E43: https://www.bmwk.de/Redaktion/DE/Downloads/E/energiewende-in-der-industrie-ap2a-branchensteckbrief-metall.pdf?__blob=publicationFile&v=4 | F43: Navigant Energy Germany GmbH, Institut für Energiewirtschaft und Rationelle Energieanwendung, Forschungsgesellschaft für Energiewirtschaft, BBG und Partner | G43: Energiewende in der Industrie: Branchensteckbrief der NE-Metallindustrie | I43: 2020 | J43: 02.11.2023
C44: Der spezifische Strombedarf für die NE-Metallgießereien beträgt etwa 1,5 MWh/t. Insgesamt ergibt sich für die NE-Metallgießereien ein spezifischer Energieverbrauch von 3,6 MWh/t. | D44: elec: 1,5/1000*3600 = 5,4 GJ/t for casting fuel: (3,6-1,5)/1000*3600 = 7,56 GJ/t for casting
A46: Further Info: | B46: F1 | C46: from flotation till processing processing | D46: total: 8.54 GJ/t (Germany) or 10.29 (EU) + processing: 5.8 GJ/t | E46: https://d-nb.info/1049260554/34
B47: F2 | C47: Row ore and concentrate processing from flotation till processing | D47: elec 3,54 GJ/t, Diesel 2.7 GJ/t elec: 4.4 GJ/t, fuel: 6.3 GJ/t | E47: https://www.umweltbundesamt.at/fileadmin/site/publikationen/REP0303.pdf | H47: p. 44
A49: copper_sec
A50: Source: | B50: [1] | C50: Sekundärkupfer ähnlich hoher spezifischer Stromverbrauch 0,64 MWh/t . In der Sekundärkupferproduktion sind lediglich etwa 50 Prozent des Brennstoffbedarfs der Primärkupferherstellung erforderlich (1,1 MWh/t) | D50: elec: 0,64/1000*3600 = 2,30 GJ/t fuel: 1,1MWh/1000*3600 = 3,96 GJ/t | E50: https://www.bmwk.de/Redaktion/DE/Downloads/E/energiewende-in-der-industrie-ap2a-branchensteckbrief-metall.pdf?__blob=publicationFile&v=4 | F50: Navigant Energy Germany GmbH, Institut für Energiewirtschaft und Rationelle Energieanwendung, Forschungsgesellschaft für Energiewirtschaft, BBG und Partner | G50: Energiewende in der Industrie: Branchensteckbrief der NE-Metallindustrie | I50: 2020 | J50: 02.11.2023
C51: Der spezifische Strombedarf für die NE-Metallgießereien beträgt etwa 1,5 MWh/t. Insgesamt ergibt sich für die NE-Metallgießereien ein spezifischer Energieverbrauch von 3,6 MWh/t. | D51: elec: 1,5/1000*3600 = 5,4 GJ/t for casting fuel: (3,6-1,5)/1000*3600 = 7,56 GJ/t for casting
A53: Further Info: | B53: F1 | C53: from flotation till processing processing | D53: total: 6.3 GJ/t (Germany) or 6.5 (EU) + processing: 5.8 GJ/t | E53: https://d-nb.info/1049260554/34
B54: F2 | C54: from flotation till processing | D54: elec 2.16GJ/t, fuel (Gas) 4.6 GJ/t | E54: https://www.umweltbundesamt.at/fileadmin/site/publikationen/REP0303.pdf | H54: p. 47
A56: chlorine
A57: Source: | B57: [1] | C57: Der spezifische Energieverbrauch des Membranverfahrens ist mit 9,2-9,8GJ/t am geringsten. Davon entfallen 0,6GJ/t auf den Dampfbedarf zur Eindampfung und auf Konzentration der Lauge. | E57: https://d-nb.info/1049260554/34 | F57: Institut für Energiewirtschaft und Rationelle Energieanwendung, Stuttgart | G57: Energieeffizienz in der Industrie: Modellgestützte Analyse des effizienten Energieeinsatzes in der EU-27 mit Fokus auf den Industriesektor | H57: p.75 | I57: 2014 | J57: 02.11.2023 | K57: Kuder, Ralf
...
